<?xml version='1.0'?>

<robot name="atom" xmlns:xacro="http://www.ros.org/wiki/xacro">
	<xacro:property name="robot_name" value="atom" />
	<xacro:property name="robot_chassis_mass" value="15"/>
	<xacro:property name="robot_chassis_length" value="0.2"/>
	<xacro:property name="robot_chassis_radius" value="0.25"/>
	<xacro:property name="robot_caster_wheel_radius" value="0.05"/>
	<xacro:property name="robot_caster_wheel_radius_collision" value="0.0499"/>

	<xacro:property name="robot_wheel_mass" value="5"/>
	<xacro:property name="robot_wheel_length" value="0.05"/>
	<xacro:property name="robot_wheel_radius" value="0.1"/>

	<xacro:property name="camera_mass" value="0.1"/>
	<xacro:property name="hokoyu_mass" value="1e-5"/>

  	<material name="blue">
    	<color rgba= "0 0 1 1"/>
  	</material>
  	<material name="grey">
    	<color rgba="0.75 0.75 0.75 1"/>
  	</material>

	<!-- Make Chassis of Bot -->
	<link name="chassis">
		<pose>0 0 0.1 0 0 0</pose>

		<inertial>
			<mass value="${robot_chassis_mass}"/>
      		<origin xyz="0.0 0 0" rpy=" 0 0 0"/>

      		<inertia 
      			ixx="0.147116667" ixy="0" ixz="0"
      			iyy="0.334951167" iyz="0"
      			izz="0.3978345"
      		/>
		</inertial>

		<collision name="collision">
			<origin xyz="0 0 0.05" rpy=" 0 0 0"/>
			<geometry>
				<box size="0.5 0.5 0.2"/>
			</geometry>
		</collision>

		<visual name="chassis_visual">
			<origin xyz="0 0 0.05" rpy=" 0 0 0"/>
			<geometry>
				<box size="0.5 0.5 0.2"/>
			</geometry>
      <material name="blue"/>
		</visual>

	</link>

	<!-- Make lidar_mount of Bot -->
	<link name="3dlidar_mount">
		<pose>0 0 0.1 0 0 0</pose>

		<inertial>
			<mass value="${robot_chassis_mass}"/>
      		<origin xyz="0.0 0 0" rpy=" 0 0 0"/>

      		<inertia 
      			ixx="0.147116667" ixy="0" ixz="0"
      			iyy="0.334951167" iyz="0"
      			izz="0.3978345"
      		/>
		</inertial>

		<collision name="collision">
			<origin xyz="0 0 0.05" rpy=" 0 0 0"/>
			<geometry>
				<box size="0.12 0.12 0.15"/>
			</geometry>
		</collision>

		<visual name="chassis_visual">
			<origin xyz="0 0 0.05" rpy=" 0 0 0"/>
			<geometry>
				<box size="0.12 0.12 0.15"/>
			</geometry>

		</visual>

	</link>

	<!-- Right Wheel Back -->
	<link name="right_wheel_back">
		<inertial>
			<mass value="${robot_wheel_mass}"/>
			<origin xyz="0 0 0" rpy="0 1.5707 1.5707"/>
			<inertia
				ixx="0.1" ixy="0.0" ixz="0.0"
				iyy="0.1" iyz="0.0"
				izz="0.1"
			/>
		</inertial>

		<visual>
			<origin xyz="0 0 0" rpy="0 1.5707 1.5707"/>
			<geometry>
				<cylinder radius="${robot_wheel_radius}" length="${robot_wheel_length}"/>
			</geometry>
		</visual>

		<collision>
			<origin xyz="0 0 0" rpy="0 1.5707 1.5707"/>
			<geometry>
				<cylinder radius="${robot_wheel_radius}" length="${robot_wheel_length}"/>
			</geometry>
		</collision>

	</link>

	<!-- Right Wheel Front-->
	<link name="right_wheel_front">
		<inertial>
			<mass value="${robot_wheel_mass}"/>
			<origin xyz="0 0 0" rpy="0 1.5707 1.5707"/>
			<inertia
				ixx="0.1" ixy="0.0" ixz="0.0"
				iyy="0.1" iyz="0.0"
				izz="0.1"
			/>
		</inertial>

		<visual>
			<origin xyz="0 0 0" rpy="0 1.5707 1.5707"/>
			<geometry>
				<cylinder radius="${robot_wheel_radius}" length="${robot_wheel_length}"/>
			</geometry>
		</visual>

		<collision>
			<origin xyz="0 0 0" rpy="0 1.5707 1.5707"/>
			<geometry>
				<cylinder radius="${robot_wheel_radius}" length="${robot_wheel_length}"/>
			</geometry>
		</collision>

	</link>



	<!-- Left wheel Back-->
	<link name="left_wheel_back">
		<inertial>
			<mass value="${robot_wheel_mass}"/>
			<origin xyz="0 0 0" rpy="0 1.5707 1.5707"/>
			<inertia
				ixx="0.1" ixy="0.0" ixz="0.0"
				iyy="0.1" iyz="0.0"
				izz="0.1"
			/>
		</inertial>

		<visual>
			<origin xyz="0 0 0" rpy="0 1.5707 1.5707"/>
			<geometry>
				<cylinder radius="${robot_wheel_radius}" length="${robot_wheel_length}"/>
			</geometry>
		</visual>

		<collision>
			<origin xyz="0 0 0" rpy="0 1.5707 1.5707"/>
			<geometry>
				<cylinder radius="${robot_wheel_radius}" length="${robot_wheel_length}"/>
			</geometry>
		</collision>

	</link>

	<!-- Left wheel Front-->
	<link name="left_wheel_front">
		<inertial>
			<mass value="${robot_wheel_mass}"/>
			<origin xyz="0 0 0" rpy="0 1.5707 1.5707"/>
			<inertia
				ixx="0.1" ixy="0.0" ixz="0.0"
				iyy="0.1" iyz="0.0"
				izz="0.1"
			/>
		</inertial>

		<visual>
			<origin xyz="0 0 0" rpy="0 1.5707 1.5707"/>
			<geometry>
				<cylinder radius="${robot_wheel_radius}" length="${robot_wheel_length}"/>
			</geometry>
		</visual>

		<collision>
			<origin xyz="0 0 0" rpy="0 1.5707 1.5707"/>
			<geometry>
				<cylinder radius="${robot_wheel_radius}" length="${robot_wheel_length}"/>
			</geometry>
		</collision>

	</link>

	<!-- Camera -->
	<link name="camera">
		<inertial>
			<mass value="${camera_mass}"/>
			<origin xyz="0 0 0" rpy="0 0 0"/>
			<inertia
		        ixx="1e-6" ixy="0.0" ixz="0.0"
		        iyy="1e-6" iyz="0.0"
		        izz="1e-6"
		      />
		</inertial>

		<visual>
			<origin xyz="0 0 0" rpy="0 0 0"/>
			<geometry>
				<box size="0.05 0.05 0.05"/>
			</geometry>
      <material name="white">
        <color rgba="1 1 1 1"/>
      </material>
		</visual>

		<collision>
			<origin xyz="0 0 0" rpy="0 0 0"/>
			<geometry>
				<box size="0.05 0.05 0.05"/>
			</geometry>
		</collision>
	</link>


	<!-- Hokuyo Lidar -->
	<link name="hokuyo">
		<inertial>
			<mass value="${hokoyu_mass}"/>
			<origin xyz="0 0 0" rpy="0 0 0"/>

			<inertia
		        ixx="1e-6" ixy="0.0" ixz="0.0"
		        iyy="1e-6" iyz="0.0"
		        izz="1e-6"
		      />
		</inertial>

		<visual>
			<origin xyz="0 0 0" rpy="0 0 0"/>
			<geometry>
				<mesh filename="package://atom/meshes/hokuyo.dae"/>
			</geometry>
		</visual>

		<collision>
			<origin xyz="0 0 0" rpy="0 0 0"/>
			<geometry>
				<box size="0.1 0.1 0.1"/>
			</geometry>
		</collision>
	</link>

	<!-- Project center to the ground -->
	<link name="robot_footprint"></link>


<!-- Give the base link a unique name -->
 <link name="3dlidar_base">

    <!-- Offset the base by half the lenght of the cylinder -->
    <pose>0 0 0.029335 0 0 0</pose>

	<inertial>
      <mass value="1.2"/>
	  <origin xyz="0 0 0.05" rpy=" 0 0 0"/>

      <inertia
        ixx="0.001087473"
        iyy="0.001087473"
        izz="0.001092437"
        ixy="0"
        ixz="0"
        iyz="0"
      />
    </inertial>
    <collision name="base_collision">
	    <origin xyz="0 0 0.05" rpy=" 0 0 0"/>
        <geometry>
			<cylinder length=".05867" radius=".04267"/>
        </geometry>
    </collision>

    <!-- The visual is mostly a copy of the collision -->
    <visual name="base_visual">
		<origin xyz="0 0 0.009" rpy=" 0 0 0"/>
      	<geometry>
        	<cylinder length=".05867" radius=".04267"/>
      	</geometry>
    </visual>
  </link> -->


  <!-- Give the base link a unique name -->
  <link name="3dlidar_top">

    <!-- Vertically offset the top cylinder by the length of the bottom
        cylinder and half the length of this cylinder. -->
    <pose>0 0 0.095455 0 0 0</pose>
	<inertial>
		<mass value="0.1"/>
		<inertia
        ixx="0.000090623"
        iyy="0.000090623"
        izz="0.000091036"
        ixy="0"
        ixz="0"
        iyz="0"
      />
   </inertial>
    <collision name="top_collision">
      <geometry>
	  <cylinder length="0.07357" radius=".04267"/>
      </geometry>
    </collision>

    <!-- The visual is mostly a copy of the collision -->
    <visual name="top_visual">
      <geometry>
	  <cylinder length="0.07357" radius=".04267"/>
      </geometry>
    </visual>
  </link>


	<!-- Define Joints -->

  <!-- Each joint must have a unique name -->
<joint name="3dlidar_baseTop_joint" type="revolute">

  <!-- Position the joint at the bottom of the top link -->
  <origin xyz="0 0 -0.05" rpy="0 0 0"/>

  <!-- Use the base link as the parent of the joint -->
  <parent link="3dlidar_base" />

  <!-- Use the top link as the child of the joint -->
  <child link="3dlidar_top" />

  <!-- The axis defines the joint's degree of freedom -->
  <axis xyz="0 0 1" />

    <!-- Limit refers to the range of motion of the joint -->
   <limit
      lower="-10000000000000000"
      upper="10000000000000000"
      velocity="2"
	    effort="1"
    />
  
</joint>

	<!-- Right Wheel Joint Back-->
	<joint type="continuous" name="right_wheel_hinge_back">
	    <origin xyz="-0.2 -0.30 0" rpy="0 0 0" />
	    <parent link="chassis"/>
	    <child link="right_wheel_back" />
	    <axis xyz="0 1 0" rpy="0 0 0" />
	    <limit effort="10000" velocity="1000" />
	    <dynamics damping="1.0" friction="1.0" />
	</joint>

	<!-- Right Wheel Joint Front-->
	<joint type="continuous" name="right_wheel_hinge_front">
	    <origin xyz="0.2 -0.30 0" rpy="0 0 0" />
	    <parent link="chassis"/>
	    <child link="right_wheel_front" />
	    <axis xyz="0 1 0" rpy="0 0 0" />
	    <limit effort="10000" velocity="1000" />
	    <dynamics damping="1.0" friction="1.0" />
	</joint>


	<!-- Left Wheel Joint Back-->
	<joint type="continuous" name="left_wheel_hinge_back">
	    <origin xyz="-0.2 0.30 0" rpy="0 0 0" />
	    <parent link="chassis"/>
	    <child link="left_wheel_back" />
	    <axis xyz="0 1 0" rpy="0 0 0" />
	    <limit effort="10000" velocity="1000" />
	    <dynamics damping="1.0" friction="1.0" />
	</joint>

	<!-- Left Wheel Joint Front-->
	<joint type="continuous" name="left_wheel_hinge_front">
	    <origin xyz="0.2 0.30 0" rpy="0 0 0" />
	    <parent link="chassis"/>
	    <child link="left_wheel_front" />
	    <axis xyz="0 1 0" rpy="0 0 0" />
	    <limit effort="10000" velocity="1000" />
	    <dynamics damping="1.0" friction="1.0" />
	</joint>

	<!-- Camera Joint -->
	<joint name="camera_joint" type="fixed">
		<origin xyz="0.26 0 0" rpy="0 0 0" />
		<parent link="chassis"/>
		<child link="camera" />
		<axis xyz="0 1 0"/>
	</joint>



	<!-- Hokoyu Joint -->
	<joint name="hokuyo_joint" type="fixed">
	    <origin xyz="0.2 0 0.2" rpy="0 0 0" />   <!-- x y z = 0.2,0,0.2-->
	    <parent link="chassis"/>
	    <child link="hokuyo" />  
	    <axis xyz="0 1 0"/> 
	</joint>

	<!-- 3dlidar mount Joint -->
	<joint name="3dlidar_mount_joint" type="fixed">
	    <origin xyz="0.0 0 0.15" rpy="0 0 0" />
	    <parent link="chassis"/>
	    <child link="3dlidar_mount" />  
	    <axis xyz="0 1 0"/> 
	</joint>

  	<!-- 3dlidar Joint -->
	<joint name="3dlidar_joint" type="fixed">
	    <origin xyz="0.0 0 0.35" rpy="0 0 0" />
	    <parent link="chassis"/>
	    <child link="3dlidar_base" />  
	    <axis xyz="0 1 0"/> 
	</joint>



	<joint name="robot_footprint_joint" type="fixed">
		<origin xyz="0 0 0" rpy="0 0 0" />
		<parent link="robot_footprint"/>
		<child link="chassis" />
	</joint>


	<!-- Color of bot -->
	<gazebo reference="left_wheel_front">
		<material>Gazebo/Green</material>
		<kp>1000000.0</kp> <!-- kp and kd for rubber -->
		<kd>100.0</kd>
		<mu1>1.0</mu1>
		<mu2>1.0</mu2>
		<maxVel>1.0</maxVel>
		<minDepth>0.00</minDepth>
	</gazebo>

	<gazebo reference="left_wheel_back">
		<material>Gazebo/Green</material>
		<kp>1000000.0</kp> <!-- kp and kd for rubber -->
		<kd>100.0</kd>
		<mu1>1.0</mu1>
		<mu2>1.0</mu2>
		<maxVel>1.0</maxVel>
		<minDepth>0.00</minDepth>
	</gazebo>

	<gazebo reference="right_wheel_front">
		<material>Gazebo/Green</material>
		<kp>1000000.0</kp> <!-- kp and kd for rubber -->
		<kd>100.0</kd>
		<mu1>1.0</mu1>
		<mu2>1.0</mu2>
		<maxVel>1.0</maxVel>
		<minDepth>0.00</minDepth>
	</gazebo>
	<gazebo reference="right_wheel_back">
		<material>Gazebo/Green</material>
		<kp>1000000.0</kp> <!-- kp and kd for rubber -->
		<kd>100.0</kd>
		<mu1>1.0</mu1>
		<mu2>1.0</mu2>
		<maxVel>1.0</maxVel>
		<minDepth>0.00</minDepth>
	</gazebo>

	<gazebo reference="chassis">  
  	<visual>  
    <material>  
      <ambient>0.19225 0.19225 0.19225 1.0</ambient>  
      <diffuse>0.50754 0.50754 0.50754 1.0</diffuse>  
      <specular>0.508273 0.508273 0.508273 1.0</specular>  
      <emissive>0.0 0.0 0.0 0.0</emissive>  
    </material>  
 	</visual>  
	</gazebo>

	<gazebo reference="camera">  
  	<visual>  
 	<material>
 		<ambient>0.46 0.46 0.46 1.0</ambient>
  		<diffuse>0.46 0.46 0.46 1.0</diffuse>
  		<specular>0.46 0.46 0.46 1.0</specular>
  		<emissive>0.46 0.46 0.46 1.0</emissive>
	</material> 
 	</visual>  
	</gazebo>

	<!-- <gazebo reference="3dlidar_top">
    <visual>
		  <material>Gazebo/red</material>
    </visual>
	</gazebo>

	<gazebo reference="chassis">
    <visual>
		  <material>Gazebo/blue</material>
    </visual>
	</gazebo> -->

	<!-- <gazebo reference="right_wheel">
    <visual>
		  <material>Gazebo/Green</material>
    </visual>
	</gazebo> -->

	<!-- <gazebo reference="camera">
		  <material name="LightGrey">
        <uri>file://media/materials/scripts/gazebo.material</uri>
        <script>Gazebo/Black</script>
      </material>
	</gazebo> -->



	<!-- Motor, Camera and Lidar Simulation -->
	<xacro:include filename="$(find atom)/urdf/atom.gazebo" />

	<xacro:include filename="$(find velodyne_description)/urdf/VLP-16.urdf.xacro"/>
  <xacro:VLP-16 parent="chassis" name="velodyne" topic="/velodyne_points" hz="10" samples="440" gpu="false">
    <origin xyz="0 0 0.35" rpy="0 0 0" />
  </xacro:VLP-16>

</robot>
